sh: sysctl: command not found
Today:2018-03-22
start date:2018-03-01
end date:2018-03-22
http://manage.aniview.com/api/adserver/stats/report?startDate=1519855200&endDate=1521669600&dimensions=daily%2Ciid%2Cpcid%2Caid%2CnasidName&metrics=inventory%2Crequest%2Cimpression%2Cbid%2CAdLoaded&format=json&%7B%7D
200
Waterfall Optimization Report
Traceback (most recent call last):
  File "/Library/Frameworks/Python.framework/Versions/3.6/lib/python3.6/site-packages/pymysql/connections.py", line 1021, in _read_bytes
    data = self._rfile.read(num_bytes)
  File "/Library/Frameworks/Python.framework/Versions/3.6/lib/python3.6/socket.py", line 586, in readinto
    return self._sock.recv_into(b)
ConnectionResetError: [Errno 54] Connection reset by peer

During handling of the above exception, another exception occurred:

Traceback (most recent call last):
  File "/Library/Frameworks/Python.framework/Versions/3.6/lib/python3.6/site-packages/sqlalchemy/engine/base.py", line 1159, in _execute_context
    context)
  File "/Library/Frameworks/Python.framework/Versions/3.6/lib/python3.6/site-packages/sqlalchemy/dialects/mysql/mysqldb.py", line 113, in do_executemany
    rowcount = cursor.executemany(statement, parameters)
  File "/Library/Frameworks/Python.framework/Versions/3.6/lib/python3.6/site-packages/pymysql/cursors.py", line 193, in executemany
    self._get_db().encoding)
  File "/Library/Frameworks/Python.framework/Versions/3.6/lib/python3.6/site-packages/pymysql/cursors.py", line 225, in _do_execute_many
    rows += self.execute(sql + postfix)
  File "/Library/Frameworks/Python.framework/Versions/3.6/lib/python3.6/site-packages/pymysql/cursors.py", line 166, in execute
    result = self._query(query)
  File "/Library/Frameworks/Python.framework/Versions/3.6/lib/python3.6/site-packages/pymysql/cursors.py", line 322, in _query
    conn.query(q)
  File "/Library/Frameworks/Python.framework/Versions/3.6/lib/python3.6/site-packages/pymysql/connections.py", line 856, in query
    self._affected_rows = self._read_query_result(unbuffered=unbuffered)
  File "/Library/Frameworks/Python.framework/Versions/3.6/lib/python3.6/site-packages/pymysql/connections.py", line 1057, in _read_query_result
    result.read()
  File "/Library/Frameworks/Python.framework/Versions/3.6/lib/python3.6/site-packages/pymysql/connections.py", line 1340, in read
    first_packet = self.connection._read_packet()
  File "/Library/Frameworks/Python.framework/Versions/3.6/lib/python3.6/site-packages/pymysql/connections.py", line 987, in _read_packet
    packet_header = self._read_bytes(4)
  File "/Library/Frameworks/Python.framework/Versions/3.6/lib/python3.6/site-packages/pymysql/connections.py", line 1029, in _read_bytes
    "Lost connection to MySQL server during query (%s)" % (e,))
pymysql.err.OperationalError: (2013, 'Lost connection to MySQL server during query ([Errno 54] Connection reset by peer)')

The above exception was the direct cause of the following exception:

Traceback (most recent call last):
  File "Databaseconnect.py", line 80, in <module>
    tableSelect()
  File "Databaseconnect.py", line 66, in tableSelect
    sqlConnect = data.to_sql(name='WaterfallOptimization', con=connection, if_exists='replace', index=False)
  File "/Library/Frameworks/Python.framework/Versions/3.6/lib/python3.6/site-packages/pandas/core/generic.py", line 1534, in to_sql
    chunksize=chunksize, dtype=dtype)
  File "/Library/Frameworks/Python.framework/Versions/3.6/lib/python3.6/site-packages/pandas/io/sql.py", line 473, in to_sql
    chunksize=chunksize, dtype=dtype)
  File "/Library/Frameworks/Python.framework/Versions/3.6/lib/python3.6/site-packages/pandas/io/sql.py", line 1156, in to_sql
    table.insert(chunksize)
  File "/Library/Frameworks/Python.framework/Versions/3.6/lib/python3.6/site-packages/pandas/io/sql.py", line 670, in insert
    self._execute_insert(conn, keys, chunk_iter)
  File "/Library/Frameworks/Python.framework/Versions/3.6/lib/python3.6/site-packages/pandas/io/sql.py", line 645, in _execute_insert
    conn.execute(self.insert_statement(), data)
  File "/Library/Frameworks/Python.framework/Versions/3.6/lib/python3.6/site-packages/sqlalchemy/engine/base.py", line 945, in execute
    return meth(self, multiparams, params)
  File "/Library/Frameworks/Python.framework/Versions/3.6/lib/python3.6/site-packages/sqlalchemy/sql/elements.py", line 263, in _execute_on_connection
    return connection._execute_clauseelement(self, multiparams, params)
  File "/Library/Frameworks/Python.framework/Versions/3.6/lib/python3.6/site-packages/sqlalchemy/engine/base.py", line 1053, in _execute_clauseelement
    compiled_sql, distilled_params
  File "/Library/Frameworks/Python.framework/Versions/3.6/lib/python3.6/site-packages/sqlalchemy/engine/base.py", line 1189, in _execute_context
    context)
  File "/Library/Frameworks/Python.framework/Versions/3.6/lib/python3.6/site-packages/sqlalchemy/engine/base.py", line 1402, in _handle_dbapi_exception
    exc_info
  File "/Library/Frameworks/Python.framework/Versions/3.6/lib/python3.6/site-packages/sqlalchemy/util/compat.py", line 203, in raise_from_cause
    reraise(type(exception), exception, tb=exc_tb, cause=cause)
  File "/Library/Frameworks/Python.framework/Versions/3.6/lib/python3.6/site-packages/sqlalchemy/util/compat.py", line 186, in reraise
    raise value.with_traceback(tb)
  File "/Library/Frameworks/Python.framework/Versions/3.6/lib/python3.6/site-packages/sqlalchemy/engine/base.py", line 1159, in _execute_context
    context)
  File "/Library/Frameworks/Python.framework/Versions/3.6/lib/python3.6/site-packages/sqlalchemy/dialects/mysql/mysqldb.py", line 113, in do_executemany
    rowcount = cursor.executemany(statement, parameters)
  File "/Library/Frameworks/Python.framework/Versions/3.6/lib/python3.6/site-packages/pymysql/cursors.py", line 193, in executemany
    self._get_db().encoding)
  File "/Library/Frameworks/Python.framework/Versions/3.6/lib/python3.6/site-packages/pymysql/cursors.py", line 225, in _do_execute_many
    rows += self.execute(sql + postfix)
  File "/Library/Frameworks/Python.framework/Versions/3.6/lib/python3.6/site-packages/pymysql/cursors.py", line 166, in execute
    result = self._query(query)
  File "/Library/Frameworks/Python.framework/Versions/3.6/lib/python3.6/site-packages/pymysql/cursors.py", line 322, in _query
    conn.query(q)
  File "/Library/Frameworks/Python.framework/Versions/3.6/lib/python3.6/site-packages/pymysql/connections.py", line 856, in query
    self._affected_rows = self._read_query_result(unbuffered=unbuffered)
  File "/Library/Frameworks/Python.framework/Versions/3.6/lib/python3.6/site-packages/pymysql/connections.py", line 1057, in _read_query_result
    result.read()
  File "/Library/Frameworks/Python.framework/Versions/3.6/lib/python3.6/site-packages/pymysql/connections.py", line 1340, in read
    first_packet = self.connection._read_packet()
  File "/Library/Frameworks/Python.framework/Versions/3.6/lib/python3.6/site-packages/pymysql/connections.py", line 987, in _read_packet
    packet_header = self._read_bytes(4)
  File "/Library/Frameworks/Python.framework/Versions/3.6/lib/python3.6/site-packages/pymysql/connections.py", line 1029, in _read_bytes
    "Lost connection to MySQL server during query (%s)" % (e,))
sqlalchemy.exc.OperationalError: (pymysql.err.OperationalError) (2013, 'Lost connection to MySQL server during query ([Errno 54] Connection reset by peer)') [SQL: 'INSERT INTO `WaterfallOptimization` (`Date`, `Pub_id`, `Pub_Channel_id`, `AdSource_Name`, `Advertiser`, `Inventory`, `Request`, `Impression`, `Bid`, `AdLoaded`) VALUES (%(Date)s, %(Pub_id)s, %(Pub_Channel_id)s, %(AdSource_Name)s, %(Advertiser)s, %(Inventory)s, %(Request)s, %(Impression)s, %(Bid)s, %(AdLoaded)s)'] [parameters: ({'Date': '2018-02-28', 'Pub_id': '58224c6e0857bb7a7d8b4568', 'Pub_Channel_id': '-', 'AdSource_Name': '-', 'Advertiser': '-', 'Inventory': '11905', 'Request': '0', 'Impression': '0', 'Bid': '0', 'AdLoaded': '0'}, {'Date': '2018-02-28', 'Pub_id': '58224c6e0857bb7a7d8b4568', 'Pub_Channel_id': '-', 'AdSource_Name': 'AOL_RON 2', 'Advertiser': 'AOL 1', 'Inventory': '0', 'Request': '3254', 'Impression': '0', 'Bid': '2667', 'AdLoaded': '0'}, {'Date': '2018-02-28', 'Pub_id': '58224c6e0857bb7a7d8b4568', 'Pub_Channel_id': '-', 'AdSource_Name': 'AOL_RON 3', 'Advertiser': 'AOL 1', 'Inventory': '0', 'Request': '3121', 'Impression': '0', 'Bid': '2673', 'AdLoaded': '0'}, {'Date': '2018-02-28', 'Pub_id': '58224c6e0857bb7a7d8b4568', 'Pub_Channel_id': '-', 'AdSource_Name': 'AOL_RON 4', 'Advertiser': 'AOL 1', 'Inventory': '0', 'Request': '3240', 'Impression': '0', 'Bid': '2718', 'AdLoaded': '0'}, {'Date': '2018-02-28', 'Pub_id': '58224c6e0857bb7a7d8b4568', 'Pub_Channel_id': '-', 'AdSource_Name': 'AOL_RON 5', 'Advertiser': 'AOL 1', 'Inventory': '0', 'Request': '3095', 'Impression': '0', 'Bid': '2593', 'AdLoaded': '0'}, {'Date': '2018-02-28', 'Pub_id': '58224c6e0857bb7a7d8b4568', 'Pub_Channel_id': '-', 'AdSource_Name': 'AOL_RON 7 [6]', 'Advertiser': 'AOL 1', 'Inventory': '0', 'Request': '3406', 'Impression': '0', 'Bid': '2851', 'AdLoaded': '0'}, {'Date': '2018-02-28', 'Pub_id': '58224c6e0857bb7a7d8b4568', 'Pub_Channel_id': '-', 'AdSource_Name': 'Blutonic SS 203790 1-15-17 | MPLP | ENG | 4', 'Advertiser': 'Blutonic', 'Inventory': '0', 'Request': '730', 'Impression': '0', 'Bid': '610', 'AdLoaded': '21'}, {'Date': '2018-02-28', 'Pub_id': '58224c6e0857bb7a7d8b4568', 'Pub_Channel_id': '-', 'AdSource_Name': 'DailyEngage_AOL | LP | $6', 'Advertiser': 'Daily Engage', 'Inventory': '0', 'Request': '3343', 'Impression': '0', 'Bid': '0', 'AdLoaded': '0'}  ... displaying 10 of 30826 total bound parameter sets ...  {'Date': '2018-03-21', 'Pub_id': '5ab28ad228a06107875a355a', 'Pub_Channel_id': '57c2d1da0757bb66218b4567', 'AdSource_Name': '-', 'Advertiser': '-', 'Inventory': '1', 'Request': '0', 'Impression': '0', 'Bid': '0', 'AdLoaded': '0'}, {'Date': '2018-03-21', 'Pub_id': '5ab28ad228a06107875a355a', 'Pub_Channel_id': '5ab291fd28a061287d23c757', 'AdSource_Name': '-', 'Advertiser': '-', 'Inventory': '10', 'Request': '0', 'Impression': '0', 'Bid': '0', 'AdLoaded': '0'})]
